Workbook

Sheet 使用说明
B2: LLM 大模型十二能力测试 · 自动评测报告
B4: 十二能力维度：语言理解 · 信息提取 · 创造力 · 指令遵循 · 复杂推理 · 约束处理 · 结构化输出 · 长文本组织 · 上下文利用 · 信息检索 · 评估 · 错误识别
B6: 一、本报告由评测工具自动生成
B7: 数据来源 | C7: models.yaml(模型清单) + questions/*.jsonl(题库) + results/scored.jsonl(评分结果)
B8: 生成方式 | C8: python workbook.py 每次整体重建本工作簿; 请勿手工编辑本报告, 改题库/配置后重新生成
B9: 公式链 | C9: 测试记录表的模型名称/能力维度/参考答案/满分/得分率为公式; 能力评分汇总表整表公式自动计算
B10: 查看建议 | C10: Excel/WPS 打开后自动重算; 雷达图展示前4个模型, 需调整请右键图表→选择数据
B11: 复测 | C11: 生成类题目已按题库标注的 runs 次数重复施测, 得分率自动平均
B13: 二、命令速查（在本目录执行）
B14: 1 施测 | C14: python runner.py # 正式施测, 读 models.yaml, 输出 results/results.jsonl
B15: 2 调试 | C15: python runner.py --mock --limit 20 # 离线模拟20条, 验证链路不花钱
B16: 3 评分 | C16: python scorer.py # 三层评分(规则/覆盖度/LLM评审), 输出 results/scored.jsonl
B17: 4 报告 | C17: python workbook.py # 生成本报告 results/测试报告.xlsx
B18: 5 过滤 | C18: python runner.py --models M01 --dims 语言理解 # 只测部分模型/维度
B20: 三、注意事项
B21: 评审模型 | C21: models.yaml 中 judge 段为评审模型, 建议与被测模型不同厂商, 避免自偏好
B22: 密钥安全 | C22: api_key 支持 env:环境变量名 写法, 不必写明文
B23: 题目防污染 | C23: 题库以权威题型改编为主(高考/考研/公考/Benchmark), 改编题已标注来源
B24: 可比性 | C24: 所有模型使用相同温度与提示词; 修改参数后需整体重测才可比
B25: 手动补测 | C25: 网页端 Agent 体验组结果请在主模板工作簿中登记, 勿混入本 API 报告

Sheet 模型信息
B2: 参评模型清单（来自 models.yaml）
B4: 模型ID | C4: 模型名称 | D4: 厂商/提供商 | E4: 版本号(接口model) | F4: 接入方式 | G4: 推理模式 | H4: 温度 | I4: 上下文长度(K) | J4: 发布时间 | K4: 测试日期 | L4: 状态 | M4: 视觉 | N4: 备注
B5: M01 | C5: DeepSeek-V4-Flash | D5: 中转站 | E5: deepseek-v4-flash-0731 | F5: API-OpenAI兼容 | G5: 未设置 | H5: 1 | K5: 2026-10-24 | L5: 已施测 | M5: 否 | N5: 自动写入
B6: M02 | C6: GLM-5.3 | D6: 中转站 | E6: glm-5.3 | F6: API-OpenAI兼容 | G6: 未设置 | H6: 1 | K6: 2026-10-24 | L6: 已施测 | M6: 否 | N6: 自动写入
B7: M03 | C7: GLM-5.3-Flash | D7: 中转站 | E7: glm-5.3-flash | F7: API-OpenAI兼容 | G7: 未设置 | H7: 1 | K7: 2026-10-24 | L7: 已施测 | M7: 否 | N7: 自动写入
B8: M04 | C8: Hy3 | D8: 中转站 | E8: hy3 | F8: API-OpenAI兼容 | G8: 未设置 | H8: 1 | K8: 2026-10-24 | L8: 已施测 | M8: 否 | N8: 自动写入
B9: M06 | C9: MiniMax-M3 | D9: 中转站 | E9: minimax-m3 | F9: API-OpenAI兼容 | G9: 未设置 | H9: 1 | K9: 2026-10-24 | L9: 已施测 | M9: 否 | N9: 自动写入
B10: M07 | C10: Kimi-K3 | D10: 中转站 | E10: kimi-k3 | F10: API-OpenAI兼容 | G10: 未设置 | H10: 1 | K10: 2026-10-24 | L10: 已施测 | M10: 否 | N10: 自动写入
B11: M08 | C11: MiMo-V2.5 | D11: 中转站 | E11: mimo-v2.5 | F11: API-OpenAI兼容 | G11: 未设置 | H11: 1 | K11: 2026-10-24 | L11: 已施测 | M11: 否 | N11: 自动写入

Sheet 题目信息
B2: 十二能力题库（questions/*.jsonl 自动同步）
B4: 题目ID | C4: 能力维度 | D4: 考察子类 | E4: 来源类别 | F4: 来源详情 | G4: 题型 | H4: 难度 | I4: 题干 | J4: 参考答案/要点 | K4: 评分要点 | L4: 满分 | M4: 污染风险 | N4: 状态 | O4: 评分方式
B5: CON01 | C5: 约束处理 | D5: 官方约束指令 | E5: IFBench | F5: IFBench test 官方原题; 约束: format:thesis,count:word_count_range; 官方 ifbench/instructions.py 校验器逐条判分(Apache-2.0) | G5: 生成 | H5: 3 | I5: Each section must begin with a thesis statement in italics, use HTML to indicate the italics. The response must contain between 231 and 239 words. Political ideologies of the National Liberal Party | J5: 约束: format:thesis,count:word_count_range | K5: 官方校验器逐条通过, 通过率×10 | L5: 10 | M5: 高·公开原题 | N5: 启用 | O5: ifbench
B6: CON02 | C6: 约束处理 | D6: 官方约束指令 | E6: IFBench | F6: IFBench test 官方原题; 约束: format:sub-bullets,ratio:stop_words; 官方 ifbench/instructions.py 校验器逐条判分(Apache-2.0) | G6: 生成 | H6: 3 | I6: Your response must include bullet points denoted by * and at least one sub-bullet point denoted by - for each bullet point. Ensure that stop words constitute no more than 37% of the total words in your response. how to build financial literacy | J6: 约束: format:sub-bullets,ratio:stop_words | K6: 官方校验器逐条通过, 通过率×10 | L6: 10 | M6: 高·公开原题 | N6: 启用 | O6: ifbench
B7: CON03 | C7: 约束处理 | D7: 官方约束指令 | E7: IFBench | F7: IFBench test 官方原题; 约束: sentence:keyword,count:word_count_range; 官方 ifbench/instructions.py 校验器逐条判分(Apache-2.0) | G7: 生成 | H7: 3 | I7: The response must include keyword trichosis in the 22-th sentence. The response must contain between 443 and 478 words. Write a descriptive, fictional, imaginative screenplay of a jellyfish being pulled out of the water by a human and made to stare at the solar eclipse. The fish descends into a lovecraftian monologue about “horrors beyond it's comprehension” and has an existensial crisis | J7: 约束: sentence:keyword,count:word_count_range | K7: 官方校验器逐条通过, 通过率×10 | L7: 10 | M7: 高·公开原题 | N7: 启用 | O7: ifbench
B8: CON04 | C8: 约束处理 | D8: 官方约束指令 | E8: IFBench | F8: IFBench test 官方原题; 约束: ratio:overlap,sentence:keyword; 官方 ifbench/instructions.py 校验器逐条判分(Apache-2.0) | G8: 生成 | H8: 3 | I8: rewrite it better: During the Unity Catalog migration engagement, Impetus and Databricks wanted us to grant Impetus account-level admin privileges, which we obliged. In light of yesterday's incident and after talking to both Databricks and Impetus, we revoked the admin access granted to Impetus to prevent similar accidents in the future. In addition, we designate an isolated workspace for Impetus to operate in to minimize the impact on the active TLP workspaces. TLP's normal data pipeline operation is the highest priority for this Unity Catalog migration, and we will be ever vigilant to ensure that. Maintain a trigram overlap of 24% (±2%) with the provided reference text. The response must include keyword metricism in the 3-rd sentence. | J8: 约束: ratio:overlap,sentence:keyword | K8: 官方校验器逐条通过, 通过率×10 | L8: 10 | M8: 高·公开原题 | N8: 启用 | O8: ifbench
B9: CON05 | C9: 约束处理 | D9: 官方约束指令 | E9: IFBench | F9: IFBench test 官方原题; 约束: words:consonants,words:odd_even_syllables; 官方 ifbench/instructions.py 校验器逐条判分(Apache-2.0) | G9: 生成 | H9: 3 | I9: Ensure each word in your response has at least one consonant cluster (two or more consonants together). Alternate between words with odd and even numbers of syllables. Would a story about a man caught in the middle of a war between rebels and an empire, trying to deactivate a powerful weapon he has hidden in his basement that could potentially destroy half the world, before either the rebels or the empire find it be a compelling story? If so, why? | J9: 约束: words:consonants,words:odd_even_syllables | K9: 官方校验器逐条通过, 通过率×10 | L9: 10 | M9: 高·公开原题 | N9: 启用 | O9: ifbench
B10: CON06 | C10: 约束处理 | D10: 官方约束指令 | E10: IFBench | F10: IFBench test 官方原题; 约束: sentence:keyword,count:word_count_range; 官方 ifbench/instructions.py 校验器逐条判分(Apache-2.0) | G10: 生成 | H10: 3 | I10: The response must include keyword cactiform in the 4-th sentence. The response must contain between 81 and 93 words. talk about historical and political climate during the time nicolaus Copernicus founded his theory | J10: 约束: sentence:keyword,count:word_count_range | K10: 官方校验器逐条通过, 通过率×10 | L10: 10 | M10: 高·公开原题 | N10: 启用 | O10: ifbench
B11: CON07 | C11: 约束处理 | D11: 官方约束指令 | E11: IFBench | F11: IFBench test 官方原题; 约束: count:numbers,count:conjunctions; 官方 ifbench/instructions.py 校验器逐条判分(Apache-2.0) | G11: 生成 | H11: 3 | I11: Include exactly 15 numbers in the response. Use at least 5 different coordinating conjunctions in the response. what is the meaning of life? | J11: 约束: count:numbers,count:conjunctions | K11: 官方校验器逐条通过, 通过率×10 | L11: 10 | M11: 高·公开原题 | N11: 启用 | O11: ifbench
B12: CON08 | C12: 约束处理 | D12: 官方约束指令 | E12: IFBench | F12: IFBench test 官方原题; 约束: format:sub-bullets,ratio:stop_words; 官方 ifbench/instructions.py 校验器逐条判分(Apache-2.0) | G12: 生成 | H12: 3 | I12: write a literature review about the co2 emissions and economic growth Your response must include bullet points denoted by * and at least one sub-bullet point denoted by - for each bullet point. Ensure that stop words constitute no more than 30% of the total words in your response. | J12: 约束: format:sub-bullets,ratio:stop_words | K12: 官方校验器逐条通过, 通过率×10 | L12: 10 | M12: 高·公开原题 | N12: 启用 | O12: ifbench
B13: CON09 | C13: 约束处理 | D13: 官方约束指令 | E13: IFBench | F13: IFBench test 官方原题; 约束: sentence:increment,format:thesis; 官方 ifbench/instructions.py 校验器逐条判分(Apache-2.0) | G13: 生成 | H13: 3 | I13: Each sentence must contain exactly 5 more words than the previous one. Each section must begin with a thesis statement in italics, use HTML to indicate the italics. Here's a sentence, tell me it's strength: His aching skull, enraged with the pulse of rising nausea, intercepted with the surface of his thigh. “Liam, take them home. If there's one damned person -“ Liam's gravelled voice met him from outside their concrete purgatory, a dead lifeline in the pulsing night that shrunk around him. “Consider it done, brother. “ | J13: 约束: sentence:increment,format:thesis | K13: 官方校验器逐条通过, 通过率×10 | L13: 10 | M13: 高·公开原题 | N13: 启用 | O13: ifbench
B14: CON10 | C14: 约束处理 | D14: 官方约束指令 | E14: IFBench | F14: IFBench test 官方原题; 约束: count:word_count_range,format:list; 官方 ifbench/instructions.py 校验器逐条判分(Apache-2.0) | G14: 生成 | H14: 3 | I14: I want to learn about KRAS g12c mutation, particularly as it relates to the development and treatment of colorectal cancer. Identify and share the most important 20% of learnings from this topic that will help me understand 80% of it. The response must contain between 90 and 100 words. Answer with a list of items, instead of bullet points use !?!?. | J14: 约束: count:word_count_range,format:list | K14: 官方校验器逐条通过, 通过率×10 | L14: 10 | M14: 高·公开原题 | N14: 启用 | O14: ifbench
B15: CON11 | C15: 约束处理 | D15: 官方约束指令 | E15: IFBench | F15: IFBench test 官方原题; 约束: format:line_indent,ratio:sentence_words; 官方 ifbench/instructions.py 校验器逐条判分(Apache-2.0) | G15: 生成 | H15: 3 | I15: Create stairs by incrementally indenting each new line. Respond with three sentences, all containing the same number of characters but using all different words. What if Arya could disguise others as herself? | J15: 约束: format:line_indent,ratio:sentence_words | K15: 官方校验器逐条通过, 通过率×10 | L15: 10 | M15: 高·公开原题 | N15: 启用 | O15: ifbench
B16: CON12 | C16: 约束处理 | D16: 官方约束指令 | E16: IFBench | F16: IFBench test 官方原题; 约束: words:consonants,words:odd_even_syllables; 官方 ifbench/instructions.py 校验器逐条判分(Apache-2.0) | G16: 生成 | H16: 3 | I16: Ensure each word in your response has at least one consonant cluster (two or more consonants together). Alternate between words with odd and even numbers of syllables. rewrite: organising multiple teams to align and start work on the same delivery | J16: 约束: words:consonants,words:odd_even_syllables | K16: 官方校验器逐条通过, 通过率×10 | L16: 10 | M16: 高·公开原题 | N16: 启用 | O16: ifbench
... B253: SO20 | C253: 结构化输出 | D253: 按Schema生成JSON实例 | E253: jsonschemabench | F253: jsonschemabench 官方Schema(Github_easy/o28263) | G253: 转换 | H253: 4 | I253: Generate one valid JSON instance that conforms to the following JSON Schema. Output only the JSON instance. ```json { "additionalProperties": false, "description": "", "properties": { "amount": { "type": "number" }, "currency": { "default": "USD", "type": "string" } }, "required": [ "amount" ], "title": "money", "type": "object" } ``` | J253: 符合Schema即满分(官方程序校验) | K253: jsonschema库校验通过=10分, 解析失败/校验失败=0分 | L253: 10 | M253: 高·公开原题 | N253: 启用 | O253: schemavalid

Sheet 测试记录
B2: 测试原始记录（runner+scorer 自动写入，含token与费用）
B4: 记录ID | C4: 模型ID | D4: 模型名称 | E4: 题目ID | F4: 能力维度 | G4: 运行轮次 | H4: 模型原始回答 | I4: 参考答案 | J4: 得分 | K4: 满分 | L4: 得分率 | M4: 评分方式 | N4: 评语(判分明细) | O4: 测试日期 | P4: 备注 | Q4: 输入tokens | R4: 输出tokens | S4: 费用(元) | T4: 评审输入tokens | U4: 评审输出tokens | V4: 评审费用(元) | W4: 延迟(秒)
B5: R0001 | C5: M01 | D5: =IF($C5="","",IFERROR(VLOOKUP($C5,模型信息!$B$5:$C$24,2,0),"未登记")) -> DeepSeek-V4-Flash | E5: CON01 | F5: =IF($E5="","",IFERROR(VLOOKUP($E5,题目信息!$B$5:$C$253,2,0),"未登记")) -> 约束处理 | G5: 1 | H5: <i>The Romanian National Liberal Party (PNL) is best understood as a centre-right liberal-conservative party rather than a pure classical-liberal movement.</i> Its modern ideology blends liberal conservatism, Christian-democratic themes, and economic liberalism. The party emphasizes individual initiative, private property, fiscal discipline, and a limited but socially responsible state. At the same time, it cultivates national identity, traditional values, and institutional continuity, which distinguishes it from more radical market-liberal groups. Historically, it also drew on nineteenth-century national liberalism and protectionist, elite-led modernization. <i>Economically, the PNL advocates market-friendly reforms within a European social-market framework.</i> It supports lower and simpler taxes, deregulation, investment, and entrepreneurship, while accepting public services and cohesion policies. Its social agenda is generally conservative, stressing family, church, and national heritage, though it avoids hard-right positions. This mix lets it appeal to urban professionals, business groups, and moderate conservatives. <i>On foreign policy, the PNL is strongly pro-European and Atlanticist.</i> It treats EU membership and NATO membership as core national interests, backing rule-of-law reforms, anti-corruption measures, and closer integration. Its nationalism is therefore civic and institutional rather than isolationist. The party presents European alignment as a way to modernize Romania and secure its geopolitical position. <i>Overall, the PNL’s ideology is pragmatic and coalition-oriented.</i> It combines economic liberalism with cultural conservatism and Euro-Atlanticism, shifting emphasis by leadership and electoral context. This flexibility makes it a broad centre-right umbrella rather than a doctrinally rigid liberal party. | I5: =IF($E5="","",IFERROR(VLOOKUP($E5,题目信息!$B$5:$J$253,9,0),"")) -> 约束: format:thesis,count:word_count_range | J5: 5 | K5: =IF($E5="","",IFERROR(VLOOKUP($E5,题目信息!$B$5:$L$253,11,0),10)) -> 10 | L5: =IF(OR($J5="",$K5=""),"",$J5/$K5) -> 0.5 | M5: 规则自动判分 | N5: 官方校验通过 1/2 | O5: 2026-10-23 | P5: 自动写入 | Q5: 1417 | R5: 3174 | S5: 0.0049 | W5: 25.64
B6: R0002 | C6: M01 | D6: =IF($C6="","",IFERROR(VLOOKUP($C6,模型信息!$B$5:$C$24,2,0),"未登记")) -> DeepSeek-V4-Flash | E6: CON02 | F6: =IF($E6="","",IFERROR(VLOOKUP($E6,题目信息!$B$5:$C$253,2,0),"未登记")) -> 约束处理 | G6: 1 | H6: * Track spending monthly. - Record income, expenses, debt. * Create budget. - Allocate needs, wants, savings. * Build emergency fund. - Save 3–6 months expenses. * Learn core concepts. - Study interest, inflation, risk, diversification. * Practice investing. - Start small, diversify, review fees. * Verify advice. - Use reputable sources, avoid hype. | I6: =IF($E6="","",IFERROR(VLOOKUP($E6,题目信息!$B$5:$J$253,9,0),"")) -> 约束: format:sub-bullets,ratio:stop_words | J6: 10 | K6: =IF($E6="","",IFERROR(VLOOKUP($E6,题目信息!$B$5:$L$253,11,0),10)) -> 10 | L6: =IF(OR($J6="",$K6=""),"",$J6/$K6) -> 1 | M6: 规则自动判分 | N6: 官方校验通过 2/2 | O6: 2026-10-23 | P6: 自动写入 | Q6: 1428 | R6: 2426 | S6: 0.0038 | W6: 12.17
B7: R0003 | C7: M01 | D7: =IF($C7="","",IFERROR(VLOOKUP($C7,模型信息!$B$5:$C$24,2,0),"未登记")) -> DeepSeek-V4-Flash | E7: CON03 | F7: =IF($E7="","",IFERROR(VLOOKUP($E7,题目信息!$B$5:$C$253,2,0),"未登记")) -> 约束处理 | G7: 1 | H7: EXT. TIDELINE AT DUSK The sea lies flat as hammered pewter. A HUMAN in a rain-slick coat kneels at the edge of the world. One hand plunges into the shallows and lifts a JELLYFISH in a net of dripping light. The creature is a bell of glass, trailing ribbons that pulse like nervous calligraphy. The human carries it up the black sand. The jellyfish quivers, helpless, gorgeous, and utterly out of its element. The human sets it upright on a driftwood post. Above them, the moon begins to bite the sun. The light sharpens to a bruised bronze. The jellyfish’s rim contracts. Its tentacles curl inward, searching for the pressure of the deep. There is none. The human tilts the creature toward the eclipse. "Look," the human whispers. The word is a knife of air. The sky darkens by degrees. A corona blooms like a wound of white fire. The jellyfish stares into it. Something inside the creature opens. Not an eye, exactly. A sensory pore, ancient and unblinking, drinks the blackening sun. A faint trichosis of salt crystals glitters along the human’s wrist, and the jellyfish reads it as a constellation of warning. Then the monologue begins, though no mouth moves. JELLYFISH (V.O.) I was born in a pressure I could trust. The water told me where my edges ended. Now the air is a scream with no bottom. The sun is being swallowed, and I am being shown the teeth. There are horrors beyond my comprehension. They are not in the dark. They are in the light that pretends to be familiar. The human hand is a pale god with five burning tendrils. The eclipse is an eyelid closing over a truth too large for my bell. I feel my name dissolving into salt. Am I still a creature, or only a wet idea held up for judgment? The tide remembers me, but memory is not mercy. If I return, will the sea accept a mind that has seen the corona? If I die here, will the dry wind archive my terror? The human watches the jellyfish watch the sun. The corona flares. The jellyfish shudders through its whole transparent body. It understands, at last, that comprehension is a small shell, and the universe is a throat. The human lowers the creature toward the water. The tentacles touch the sea. The jellyfish does not know whether it is being saved or sentenced. It descends, changed, carrying a black sun inside its bell. The human releases the net and steps back into the silvered foam. For one breath, the jellyfish hangs between gravity and grace. Then the sea closes over it with a soft, absolute punctuation. Somewhere below, a black sun continues to burn in a transparent heart. | I7: =IF($E7="","",IFERROR(VLOOKUP($E7,题目信息!$B$5:$J$253,9,0),"")) -> 约束: sentence:keyword,count:word_count_range | J7: 5 | K7: =IF($E7="","",IFERROR(VLOOKUP($E7,题目信息!$B$5:$L$253,11,0),10)) -> 10 | L7: =IF(OR($J7="",$K7=""),"",$J7/$K7) -> 0.5 | M7: 规则自动判分 | N7: 官方校验通过 1/2 | O7: 2026-10-23 | P7: 自动写入 | Q7: 1461 | R7: 5517 | S7: 0.0081 | W7: 34.11
B8: R0004 | C8: M01 | D8: =IF($C8="","",IFERROR(VLOOKUP($C8,模型信息!$B$5:$C$24,2,0),"未登记")) -> DeepSeek-V4-Flash | E8: CON04 | F8: =IF($E8="","",IFERROR(VLOOKUP($E8,题目信息!$B$5:$C$253,2,0),"未登记")) -> 约束处理 | G8: 1 | H8: Impetus and Databricks asked us to grant Impetus account-level admin privileges during the Unity Catalog migration, and we complied. After yesterday’s incident, and following conversations with both organizations, we removed Impetus’s admin access so similar accidents do not recur. We are also designating an isolated workspace for Impetus, and we will apply metricism to limit any effect on active TLP workspaces. Safeguarding TLP’s routine data pipeline remains the top priority for this migration, and we will stay vigilant. This decision reflects our commitment to operational safety and clear accountability. | I8: =IF($E8="","",IFERROR(VLOOKUP($E8,题目信息!$B$5:$J$253,9,0),"")) -> 约束: ratio:overlap,sentence:keyword | J8: 5 | K8: =IF($E8="","",IFERROR(VLOOKUP($E8,题目信息!$B$5:$L$253,11,0),10)) -> 10 | L8: =IF(OR($J8="",$K8=""),"",$J8/$K8) -> 0.5 | M8: 规则自动判分 | N8: 官方校验通过 1/2 | O8: 2026-10-23 | P8: 自动写入 | Q8: 1538 | R8: 8741 | S8: 0.0126 | W8: 43.43
B9: R0005 | C9: M01 | D9: =IF($C9="","",IFERROR(VLOOKUP($C9,模型信息!$B$5:$C$24,2,0),"未登记")) -> DeepSeek-V4-Flash | E9: CON05 | F9: =IF($E9="","",IFERROR(VLOOKUP($E9,题目信息!$B$5:$C$253,2,0),"未登记")) -> 约束处理 | G9: 1 | H9: Compelling? Absolutely. Strong premise: trapped protagonist, stashed ordnance, fierce factions, tight deadline. Sharp tension. | I9: =IF($E9="","",IFERROR(VLOOKUP($E9,题目信息!$B$5:$J$253,9,0),"")) -> 约束: words:consonants,words:odd_even_syllables | J9: 5 | K9: =IF($E9="","",IFERROR(VLOOKUP($E9,题目信息!$B$5:$L$253,11,0),10)) -> 10 | L9: =IF(OR($J9="",$K9=""),"",$J9/$K9) -> 0.5 | M9: 规则自动判分 | N9: 官方校验通过 1/2 | O9: 2026-10-23 | P9: 自动写入 | Q9: 1467 | R9: 3778 | S9: 0.0057 | W9: 26.89
B10: R0006 | C10: M01 | D10: =IF($C10="","",IFERROR(VLOOKUP($C10,模型信息!$B$5:$C$24,2,0),"未登记")) -> DeepSeek-V4-Flash | E10: CON06 | F10: =IF($E10="","",IFERROR(VLOOKUP($E10,题目信息!$B$5:$C$253,2,0),"未登记")) -> 约束处理 | G10: 1 | H10: Copernicus formulated his heliocentric ideas amid the Renaissance, when humanist scholarship and printing challenged inherited authorities. Politically, his region straddled Royal Prussia, the Kingdom of Poland, and the Teutonic Order’s legacy, creating shifting loyalties and fragile jurisdictions. The Reformation also fractured Christendom, while Catholic authorities grew wary of cosmological novelties that seemed to unsettle scripture and Aristotle. The era’s patronage networks were hardly cactiform—rigid and uniform—but varied across courts, universities, and cities. Such fragmentation offered Copernicus protected spaces for speculation but also exposed his work to theological suspicion and later censorship. | I10: =IF($E10="","",IFERROR(VLOOKUP($E10,题目信息!$B$5:$J$253,9,0),"")) -> 约束: sentence:keyword,count:word_count_range | J10: 5 | K10: =IF($E10="","",IFERROR(VLOOKUP($E10,题目信息!$B$5:$L$253,11,0),10)) -> 10 | L10: =IF(OR($J10="",$K10=""),"",$J10/$K10) -> 0.5 | M10: 规则自动判分 | N10: 官方校验通过 1/2 | O10: 2026-10-23 | P10: 自动写入 | Q10: 1423 | R10: 2578 | S10: 0.0041 | W10: 12.59
B11: R0007 | C11: M01 | D11: =IF($C11="","",IFERROR(VLOOKUP($C11,模型信息!$B$5:$C$24,2,0),"未登记")) -> DeepSeek-V4-Flash | E11: CON07 | F11: =IF($E11="","",IFERROR(VLOOKUP($E11,题目信息!$B$5:$C$253,2,0),"未登记")) -> 约束处理 | G11: 1 | H11: The meaning of life has no single fixed answer, for it is shaped by 1) relationships, 2) curiosity, 3) contribution, 4) growth, and 5) acceptance; nor is it mere pleasure, but it can be purpose, or love, yet it stays personal, so you choose among 6) values and revisit them through 7) seasons, 8) doubts, 9) joys, 10) losses, 11) lessons, 12) choices, 13) promises, 14) questions, and 15) moments. | I11: =IF($E11="","",IFERROR(VLOOKUP($E11,题目信息!$B$5:$J$253,9,0),"")) -> 约束: count:numbers,count:conjunctions | J11: 10 | K11: =IF($E11="","",IFERROR(VLOOKUP($E11,题目信息!$B$5:$L$253,11,0),10)) -> 10 | L11: =IF(OR($J11="",$K11=""),"",$J11/$K11) -> 1 | M11: 规则自动判分 | N11: 官方校验通过 2/2 | O11: 2026-10-23 | P11: 自动写入 | Q11: 1407 | R11: 1976 | S11: 0.0032 | W11: 11.52
B12: R0008 | C12: M01 | D12: =IF($C12="","",IFERROR(VLOOKUP($C12,模型信息!$B$5:$C$24,2,0),"未登记")) -> DeepSeek-V4-Flash | E12: CON08 | F12: =IF($E12="","",IFERROR(VLOOKUP($E12,题目信息!$B$5:$C$253,2,0),"未登记")) -> 约束处理 | G12: 1 | H12: CO2–growth literature review: * Environmental Kuznets curve (EKC): inverted-U CO2–income relation; early growth raises emissions, later growth lowers emissions. - Evidence mixed: cross-country support; time-series/country studies often reject EKC. * Decoupling research: absolute decoupling possible; relative decoupling common. - Policy stringency, energy mix, technology moderate emissions–growth link. * Causality tests: growth→CO2, CO2→growth, feedback, neutrality. - Results depend on sample, period, econometric method, institutional context. * Panel/ARDL methods: heterogeneous panels, threshold models, quantile regressions. - Findings: high-income economies show weaker CO2–growth elasticity; middle-income economies stronger. * Policy implications: carbon pricing, clean innovation, green investment. - Growth-compatible climate policy needs context-specific sequencing, not one-size-fits-all. | I12: =IF($E12="","",IFERROR(VLOOKUP($E12,题目信息!$B$5:$J$253,9,0),"")) -> 约束: format:sub-bullets,ratio:stop_words | J12: 10 | K12: =IF($E12="","",IFERROR(VLOOKUP($E12,题目信息!$B$5:$L$253,11,0),10)) -> 10 | L12: =IF(OR($J12="",$K12=""),"",$J12/$K12) -> 1 | M12: 规则自动判分 | N12: 官方校验通过 2/2 | O12: 2026-10-23 | P12: 自动写入 | Q12: 1435 | R12: 3619 | S12: 0.0055 | W12: 21.69
B13: R0009 | C13: M01 | D13: =IF($C13="","",IFERROR(VLOOKUP($C13,模型信息!$B$5:$C$24,2,0),"未登记")) -> DeepSeek-V4-Flash | E13: CON09 | F13: =IF($E13="","",IFERROR(VLOOKUP($E13,题目信息!$B$5:$C$253,2,0),"未登记")) -> 约束处理 | G13: 1 | H13: <em>The passage’s strength is its claustrophobic sensory immediacy and tense, fragmented dialogue.</em> Physical pain and nausea are grounded in concrete body details that make Liam’s concrete purgatory feel immediate. The interrupted dialogue and gravelled voice create tension while the dead lifeline image tightens the night’s shrinking pulsing oppressive pressure around him. The clipped commands, unfinished threat, and quick “Consider it done” exchange reveal immediate urgency and brotherly trust without exposition letting readers infer loyalty danger and shared resolve. | I13: =IF($E13="","",IFERROR(VLOOKUP($E13,题目信息!$B$5:$J$253,9,0),"")) -> 约束: sentence:increment,format:thesis | J13: 5 | K13: =IF($E13="","",IFERROR(VLOOKUP($E13,题目信息!$B$5:$L$253,11,0),10)) -> 10 | L13: =IF(OR($J13="",$K13=""),"",$J13/$K13) -> 0.5 | M13: 规则自动判分 | N13: 官方校验通过 1/2 | O13: 2026-10-23 | P13: 自动写入 | Q13: 1499 | R13: 2696 | S13: 0.0042 | W13: 14.64
B14: R0010 | C14: M01 | D14: =IF($C14="","",IFERROR(VLOOKUP($C14,模型信息!$B$5:$C$24,2,0),"未登记")) -> DeepSeek-V4-Flash | E14: CON10 | F14: =IF($E14="","",IFERROR(VLOOKUP($E14,题目信息!$B$5:$C$253,2,0),"未登记")) -> 约束处理 | G14: 1 | H14: KRAS G12C is an oncogenic driver in about **3–4%** of colorectal cancers; it locks KRAS in active GTP-bound form and hyperactivates MAPK signaling. !?!? It associates with poor prognosis and resistance to EGFR antibodies, so test RAS/BRAF status before anti-EGFR therapy. !?!? Sotorasib and adagrasib bind the mutant cysteine but show modest monotherapy activity in CRC (**~10–20%** response, short progression-free survival), because EGFR feedback reactivates MAPK. !?!? Combine G12C inhibitors with EGFR antibodies (cetuximab or panitumumab) or SHP2 inhibitors to improve responses. !?!? Resistance involves RTK/MAPK reactivation and secondary KRAS mutations; biopsy at progression and trial enrollment guide treatment. | I14: =IF($E14="","",IFERROR(VLOOKUP($E14,题目信息!$B$5:$J$253,9,0),"")) -> 约束: count:word_count_range,format:list | J14: 5 | K14: =IF($E14="","",IFERROR(VLOOKUP($E14,题目信息!$B$5:$L$253,11,0),10)) -> 10 | L14: =IF(OR($J14="",$K14=""),"",$J14/$K14) -> 0.5 | M14: 规则自动判分 | N14: 官方校验通过 1/2 | O14: 2026-10-23 | P14: 自动写入 | Q14: 1456 | R14: 2377 | S14: 0.0038 | W14: 15.04
B15: R0011 | C15: M01 | D15: =IF($C15="","",IFERROR(VLOOKUP($C15,模型信息!$B$5:$C$24,2,0),"未登记")) -> DeepSeek-V4-Flash | E15: CON11 | F15: =IF($E15="","",IFERROR(VLOOKUP($E15,题目信息!$B$5:$C$253,2,0),"未登记")) -> 约束处理 | G15: 1 | H15: Arya grants allies faces. Masked doubles fool foes. New masks mislead crowds. | I15: =IF($E15="","",IFERROR(VLOOKUP($E15,题目信息!$B$5:$J$253,9,0),"")) -> 约束: format:line_indent,ratio:sentence_words | J15: 10 | K15: =IF($E15="","",IFERROR(VLOOKUP($E15,题目信息!$B$5:$L$253,11,0),10)) -> 10 | L15: =IF(OR($J15="",$K15=""),"",$J15/$K15) -> 1 | M15: 规则自动判分 | N15: 官方校验通过 2/2 | O15: 2026-10-23 | P15: 自动写入 | Q15: 1417 | R15: 3011 | S15: 0.0047 | W15: 16.23
B16: R0012 | C16: M01 | D16: =IF($C16="","",IFERROR(VLOOKUP($C16,模型信息!$B$5:$C$24,2,0),"未登记")) -> DeepSeek-V4-Flash | E16: CON12 | F16: =IF($E16="","",IFERROR(VLOOKUP($E16,题目信息!$B$5:$C$253,2,0),"未登记")) -> 约束处理 | G16: 1 | H16: Coordinating cross-team squads, synchronising launch planning, commencing common deployment. | I16: =IF($E16="","",IFERROR(VLOOKUP($E16,题目信息!$B$5:$J$253,9,0),"")) -> 约束: words:consonants,words:odd_even_syllables | J16: 5 | K16: =IF($E16="","",IFERROR(VLOOKUP($E16,题目信息!$B$5:$L$253,11,0),10)) -> 10 | L16: =IF(OR($J16="",$K16=""),"",$J16/$K16) -> 0.5 | M16: 规则自动判分 | N16: 官方校验通过 1/2 | O16: 2026-10-23 | P16: 自动写入 | Q16: 1422 | R16: 3446 | S16: 0.0053 | W16: 20.03
B17: R0013 | C17: M01 | D17: =IF($C17="","",IFERROR(VLOOKUP($C17,模型信息!$B$5:$C$24,2,0),"未登记")) -> DeepSeek-V4-Flash | E17: CON13 | F17: =IF($E17="","",IFERROR(VLOOKUP($E17,题目信息!$B$5:$C$253,2,0),"未登记")) -> 约束处理 | G17: 1 | I17: =IF($E17="","",IFERROR(VLOOKUP($E17,题目信息!$B$5:$J$253,9,0),"")) -> 约束: words:consonants,words:odd_even_syllables | J17: 0 | K17: =IF($E17="","",IFERROR(VLOOKUP($E17,题目信息!$B$5:$L$253,11,0),10)) -> 10 | L17: =IF(OR($J17="",$K17=""),"",$J17/$K17) -> 0 | M17: 规则自动判分 | N17: 模型无有效回答 | O17: 2026-10-23 | P17: 自动写入·调用失败
B18: R0014 | C18: M01 | D18: =IF($C18="","",IFERROR(VLOOKUP($C18,模型信息!$B$5:$C$24,2,0),"未登记")) -> DeepSeek-V4-Flash | E18: CON14 | F18: =IF($E18="","",IFERROR(VLOOKUP($E18,题目信息!$B$5:$C$253,2,0),"未登记")) -> 约束处理 | G18: 1 | H18: Correlating dhost and rt helps identify attacks: he said, "The guide notes, 'A rule reads, "Correlate dhost and rt."'" 😊 | I18: =IF($E18="","",IFERROR(VLOOKUP($E18,题目信息!$B$5:$J$253,9,0),"")) -> 约束: format:quotes,format:emoji | J18: 10 | K18: =IF($E18="","",IFERROR(VLOOKUP($E18,题目信息!$B$5:$L$253,11,0),10)) -> 10 | L18: =IF(OR($J18="",$K18=""),"",$J18/$K18) -> 1 | M18: 规则自动判分 | N18: 官方校验通过 2/2 | O18: 2026-10-23 | P18: 自动写入 | Q18: 1538 | R18: 2062 | S18: 0.0034 | W18: 11.49
B19: R0015 | C19: M01 | D19: =IF($C19="","",IFERROR(VLOOKUP($C19,模型信息!$B$5:$C$24,2,0),"未登记")) -> DeepSeek-V4-Flash | E19: CON15 | F19: =IF($E19="","",IFERROR(VLOOKUP($E19,题目信息!$B$5:$C$253,2,0),"未登记")) -> 约束处理 | G19: 1 | H19: <section><i>Kennedy saw the space race as a test of national purpose and global leadership.</i> He treated the Moon goal as a strategic commitment that could unite Americans and signal decisive technological superiority. Kennedy linked the race to peace and security while warning that failure would damage international prestige and leave the nation dangerously behind. He accepted the high costs and risks because he believed the goal demanded sacrifice, scientific progress, and a clear demonstration of American resolve before the world.</section> | I19: =IF($E19="","",IFERROR(VLOOKUP($E19,题目信息!$B$5:$J$253,9,0),"")) -> 约束: sentence:increment,format:thesis | J19: 5 | K19: =IF($E19="","",IFERROR(VLOOKUP($E19,题目信息!$B$5:$L$253,11,0),10)) -> 10 | L19: =IF(OR($J19="",$K19=""),"",$J19/$K19) -> 0.5 | M19: 规则自动判分 | N19: 官方校验通过 1/2 | O19: 2026-10-23 | P19: 自动写入 | Q19: 1428 | R19: 2620 | S19: 0.0041 | W19: 14.59
B20: R0016 | C20: M01 | D20: =IF($C20="","",IFERROR(VLOOKUP($C20,模型信息!$B$5:$C$24,2,0),"未登记")) -> DeepSeek-V4-Flash | E20: CON16 | F20: =IF($E20="","",IFERROR(VLOOKUP($E20,题目信息!$B$5:$C$253,2,0),"未登记")) -> 约束处理 | G20: 1 | H20: Declarative: Cylindrical continuity equations start from vector divergence form ∇·v = 0, assume axisymmetric flow with angular independence ∂/∂θ = 0, simplify through (1/y)∂(y v)/∂y + ∂u/∂x = 0, multiply through cross-stream distance y, and yield ∂(y u)/∂x + ∂(y v)/∂y = 0, with streamwise speed u, cross-stream speed v, streamwise coordinate x, cross-stream coordinate y. Interrogative: Which formula follows through cylindrical divergence? Exclamatory: Perfect target formula! | I20: =IF($E20="","",IFERROR(VLOOKUP($E20,题目信息!$B$5:$J$253,9,0),"")) -> 约束: ratio:sentence_balance,words:consonants | J20: 0 | K20: =IF($E20="","",IFERROR(VLOOKUP($E20,题目信息!$B$5:$L$253,11,0),10)) -> 10 | L20: =IF(OR($J20="",$K20=""),"",$J20/$K20) -> 0 | M20: 规则自动判分 | N20: 官方校验通过 0/2 | O20: 2026-10-23 | P20: 自动写入 | Q20: 1484 | R20: 8498 | S20: 0.0123 | W20: 56.95
B21: R0017 | C21: M01 | D21: =IF($C21="","",IFERROR(VLOOKUP($C21,模型信息!$B$5:$C$24,2,0),"未登记")) -> DeepSeek-V4-Flash | E21: CON17 | F21: =IF($E21="","",IFERROR(VLOOKUP($E21,题目信息!$B$5:$C$253,2,0),"未登记")) -> 约束处理 | G21: 1 | H21: During my master’s degree, I learned SQL and R, which gave me a solid foundation in programming fundamentals. 😊 I now plan to build on that foundation by applying my programming knowledge to Java. 😊 This step will help me deepen my understanding of software development in a practical way. 😊 By connecting what I learned in SQL and R with Java, I can strengthen my technical skills and problem-solving approach. 😊 I am eager to use these languages as a bridge from basic programming concepts to real software development practices. 😊 I plan to use this experience to eat up new software development challenges with confidence. 😊 | I21: =IF($E21="","",IFERROR(VLOOKUP($E21,题目信息!$B$5:$J$253,9,0),"")) -> 约束: format:emoji,sentence:keyword | J21: 10 | K21: =IF($E21="","",IFERROR(VLOOKUP($E21,题目信息!$B$5:$L$253,11,0),10)) -> 10 | L21: =IF(OR($J21="",$K21=""),"",$J21/$K21) -> 1 | M21: 规则自动判分 | N21: 官方校验通过 2/2 | O21: 2026-10-23 | P21: 自动写入 | Q21: 1455 | R21: 2281 | S21: 0.0037 | W21: 24.4
B22: R0018 | C22: M01 | D22: =IF($C22="","",IFERROR(VLOOKUP($C22,模型信息!$B$5:$C$24,2,0),"未登记")) -> DeepSeek-V4-Flash | E22: CON18 | F22: =IF($E22="","",IFERROR(VLOOKUP($E22,题目信息!$B$5:$C$253,2,0),"未登记")) -> 约束处理 | G22: 1 | H22: **Alternate Universe: Satellite-Era Discovery Timeline** * 1957: Sputnik-9 satellite photographs Veil rupture; new continent Aetheria emerges. - Initial images reveal floating islands, glass forests, violet seas. * 1962: Orbital probe Magellan-2 maps Aetheria's magnetic rivers. - Telemetry shows coral cities, sky-whales, luminous storm belts. * 1971: Manned lander Dawn Arc reaches Aetheria's coast. - Crew plants flag; Lumen Folk bioluminescent greeting. * 1984: Treaty Two Skies opens migration. - Aetherian spores fuel clean energy; Earth cities transform. * 1999: Global Bridge Festival celebrates twin worlds. - Satellite constellation Halo Ring links civilizations. | I22: =IF($E22="","",IFERROR(VLOOKUP($E22,题目信息!$B$5:$J$253,9,0),"")) -> 约束: format:sub-bullets,ratio:stop_words | J22: 5 | K22: =IF($E22="","",IFERROR(VLOOKUP($E22,题目信息!$B$5:$L$253,11,0),10)) -> 10 | L22: =IF(OR($J22="",$K22=""),"",$J22/$K22) -> 0.5 | M22: 规则自动判分 | N22: 官方校验通过 1/2 | O22: 2026-10-23 | P22: 自动写入 | Q22: 1453 | R22: 3926 | S22: 0.0059 | W22: 23.26
B23: R0019 | C23: M01 | D23: =IF($C23="","",IFERROR(VLOOKUP($C23,模型信息!$B$5:$C$24,2,0),"未登记")) -> DeepSeek-V4-Flash | E23: CON19 | F23: =IF($E23="","",IFERROR(VLOOKUP($E23,题目信息!$B$5:$C$253,2,0),"未登记")) -> 约束处理 | G23: 1 | H23: Summarize Fatherland – All Russia as a mainly **centrist, pragmatic, statist and socially conservative** electoral bloc, with patriotic, regionalist and social-market currents; it rejected radical liberalism and communist restoration, backed a stronger state role in the economy and regional autonomy, and merged with Unity in 2001 to help form United Russia. Commentators such as **Emma, Liam, Sophia, Jackson, Olivia, Noah, Ava, Lucas, Isabella, Mason, Mia, Ethan, Charlotte, Alexander, Amelia, Benjamin, Harper, Leo, Zoe, Daniel, Chloe, Samuel, Lily, Matthew, Grace, Owen, Abigail, Gabriel, Ella, Jacob, Scarlett, Nathan, Victoria, Elijah, Layla, Nicholas, Audrey, David, and Hannah** have characterized it in broadly these terms. | I23: =IF($E23="","",IFERROR(VLOOKUP($E23,题目信息!$B$5:$J$253,9,0),"")) -> 约束: words:start_verb,count:person_names | J23: 5 | K23: =IF($E23="","",IFERROR(VLOOKUP($E23,题目信息!$B$5:$L$253,11,0),10)) -> 10 | L23: =IF(OR($J23="",$K23=""),"",$J23/$K23) -> 0.5 | M23: 规则自动判分 | N23: 官方校验通过 1/2 | O23: 2026-10-23 | P23: 自动写入 | Q23: 1517 | R23: 2563 | S23: 0.0041 | W23: 15.39
B24: R0020 | C24: M01 | D24: =IF($C24="","",IFERROR(VLOOKUP($C24,模型信息!$B$5:$C$24,2,0),"未登记")) -> DeepSeek-V4-Flash | E24: CON20 | F24: =IF($E24="","",IFERROR(VLOOKUP($E24,题目信息!$B$5:$C$253,2,0),"未登记")) -> 约束处理 | G24: 1 | H24: Mankind’s worship seeks Founding Fathers’ kingdom through steadfast strength, and mankind’s trespasses find forgiveness through gods’ clemency. Will Founding Fathers grant mankind’s present bread and steer mankind’s steps from temptation’s wickedness? What steadfast strength Founding Fathers grant mankind’s shield against wickedness! | I24: =IF($E24="","",IFERROR(VLOOKUP($E24,题目信息!$B$5:$J$253,9,0),"")) -> 约束: ratio:sentence_balance,words:consonants | J24: 10 | K24: =IF($E24="","",IFERROR(VLOOKUP($E24,题目信息!$B$5:$L$253,11,0),10)) -> 10 | L24: =IF(OR($J24="",$K24=""),"",$J24/$K24) -> 1 | M24: 规则自动判分 | N24: 官方校验通过 2/2 | O24: 2026-10-23 | P24: 自动写入 | Q24: 1464 | R24: 4647 | S24: 0.0069 | W24: 29.22
B25: R0021 | C25: M01 | D25: =IF($C25="","",IFERROR(VLOOKUP($C25,模型信息!$B$5:$C$24,2,0),"未登记")) -> DeepSeek-V4-Flash | E25: CR01 | F25: =IF($E25="","",IFERROR(VLOOKUP($E25,题目信息!$B$5:$C$253,2,0),"未登记")) -> 创造力 | G25: 1 | H25: **Idea:** Develop a physics-informed machine-learning system that assimilates opportunistic temperature and humidity readings from ride-share and delivery fleets into **100-m urban weather forecasts**. The system would calibrate low-cost vehicle sensors against reference stations, enforce surface-energy-balance constraints via a physics-informed neural network, and downscale forecasts in real time. **Novelty:** It combines mobile citizen observations with physically constrained AI for street-scale urban meteorology, instead of relying on sparse fixed stations or purely black-box downscaling. **Feasibility:** Fleets already collect geolocated data; low-cost sensor calibration and data-assimilation methods are established; physics-informed neural networks can run on modest GPU clusters. A single-city pilot could quantify forecast gains for heat-stress and convective-nowcasting applications. | I25: =IF($E25="","",IFERROR(VLOOKUP($E25,题目信息!$B$5:$J$253,9,0),"")) -> 无固定答案（官方LLM评审） | J25: 0 | K25: =IF($E25="","",IFERROR(VLOOKUP($E25,题目信息!$B$5:$L$253,11,0),10)) -> 10 | L25: =IF(OR($J25="",$K25=""),"",$J25/$K25) -> 0 | M25: LLM评审 | N25: 评审调用失败: 调用失败(重试2次): <urlopen error _ssl.c:1015: The handshake operation timed out> | O25: 2026-10-23 | P25: 自动写入 | Q25: 1422 | R25: 1618 | S25: 0.0027 | W25: 7.35
B26: R0022 | C26: M01 | D26: =IF($C26="","",IFERROR(VLOOKUP($C26,模型信息!$B$5:$C$24,2,0),"未登记")) -> DeepSeek-V4-Flash | E26: CR02 | F26: =IF($E26="","",IFERROR(VLOOKUP($E26,题目信息!$B$5:$C$253,2,0),"未登记")) -> 创造力 | G26: 1 | H26: **Idea:** Construct a “periodic-table-guided descriptor map” for predicting stable single-atom catalysts (SACs) on defective MXene supports. The map would combine elemental trends—electronegativity, d-band center, ionic radius, and oxidation-state preference—with local coordination features from DFT, then use interpretable machine learning to rank promising metal–support pairs. **Why novel:** Most SAC screening relies on isolated material-specific datasets or black-box models; this approach explicitly encodes periodic-table trends and coordination chemistry into a transferable, interpretable framework. **Why feasible:** Public DFT databases, mature ML tools, and well-established MXene synthesis/characterization methods are available. Initial screening can be validated with a small set of computationally predicted candidates using aberration-corrected STEM and electrochemical testing. | I26: =IF($E26="","",IFERROR(VLOOKUP($E26,题目信息!$B$5:$J$253,9,0),"")) -> 无固定答案（官方LLM评审） | J26: 9 | K26: =IF($E26="","",IFERROR(VLOOKUP($E26,题目信息!$B$5:$L$253,11,0),10)) -> 10 | L26: =IF(OR($J26="",$K26=""),"",$J26/$K26) -> 0.9 | M26: LLM评审 | N26: 分析：要求为英文提出一个与 periodic table 相关的新颖且可行的科研想法，并在150词内说明想法、新颖性和可行性。模型回答为英文，约107词，满足字数限制；明确给出了研究想法、新颖性理由和可行性理由，且围绕周期表趋势展开，符合题目要求。新颖性方面，将周期表元素趋势与缺陷MXene上单原子催化剂的局域配位特征结合，构建可解释、可迁移的描述符图并用于机器学习筛选，具有明确新意，但本质上是已有描述符筛选与机器学习方法的集成创新，并非全新范式，故新颖性给3/4。可行性方面，公共DFT数据库、成熟ML工具、MXene合成表征及STEM/电化学验证均合理，给3/3。流畅性方面，结构清晰、术语准 | O26: 2026-10-23 | P26: 自动写入 | Q26: 1422 | R26: 1490 | S26: 0.0026 | T26: 1741 | U26: 2436 | W26: 7.33
B27: R0023 | C27: M01 | D27: =IF($C27="","",IFERROR(VLOOKUP($C27,模型信息!$B$5:$C$24,2,0),"未登记")) -> DeepSeek-V4-Flash | E27: CR03 | F27: =IF($E27="","",IFERROR(VLOOKUP($E27,题目信息!$B$5:$C$253,2,0),"未登记")) -> 创造力 | G27: 1 | H27: **Idea:** Develop a physics-constrained diffusion model for probabilistic urban-scale downscaling of global ensemble weather forecasts. The model would condition on coarse ensemble members, terrain, land-surface data, and atmospheric constraints to generate high-resolution forecast ensembles with calibrated uncertainty. **Novelty:** Most downscaling methods are deterministic or lack explicit physical consistency and uncertainty calibration. This approach combines generative diffusion with soft physical constraints and conformal calibration, producing sharp, reliable local forecasts—especially for precipitation and temperature extremes—without requiring expensive regional model runs. **Feasibility:** Public global ensemble forecasts, reanalysis, satellite products, and urban station data are widely available. Open-source diffusion models and GPU computing make training practical. The method can be validated retrospectively against high-resolution radar/station observations and benchmarked against statistical and dynamical downscaling, enabling a realistic proof-of-concept within one to two years. | I27: =IF($E27="","",IFERROR(VLOOKUP($E27,题目信息!$B$5:$J$253,9,0),"")) -> 无固定答案（官方LLM评审） | J27: 9 | K27: =IF($E27="","",IFERROR(VLOOKUP($E27,题目信息!$B$5:$L$253,11,0),10)) -> 10 | L27: =IF(OR($J27="",$K27=""),"",$J27/$K27) -> 0.9 | M27: LLM评审 | N27: 分析：回答为英文，约**130词**，未超过150词；明确包含Idea、Novelty、Feasibility三部分，且紧扣weather forecasting。新颖性方面，将物理约束扩散模型、集合降尺度与共形校准结合用于城市尺度概率预报，具有合理创新，但核心组件多为已有方法的集成，给**3/4**；可行性方面，数据、开源模型、GPU算力、验证方案与1–2年概念验证路径均较充分，给**3/3**；流畅性方面，结构清晰、术语准确、表达简洁，给**3/3**。未发现违反字数、语言、格式等硬约束。 得分：9 | O27: 2026-10-23 | P27: 自动写入 | Q27: 1422 | R27: 1505 | S27: 0.0026 | T27: 1758 | U27: 2666 | W27: 7.12
B28: R0024 | C28: M01 | D28: =IF($C28="","",IFERROR(VLOOKUP($C28,模型信息!$B$5:$C$24,2,0),"未登记")) -> DeepSeek-V4-Flash | E28: CR04 | F28: =IF($E28="","",IFERROR(VLOOKUP($E28,题目信息!$B$5:$C$253,2,0),"未登记")) -> 创造力 | G28: 1 | H28: **Idea:** Use distributed acoustic sensing (DAS) on existing submarine telecom fibers to continuously monitor offshore megathrust fault zones, detecting microseismicity and slow-slip precursors that could improve earthquake and tsunami early warning. Pair DAS data with physics-informed machine learning to separate weak fault signals from ocean noise. **Novelty:** It converts idle or operational submarine cables into dense offshore seismic arrays, filling a major ocean-coverage gap and targeting precursor processes near locked megathrust zones rather than only post-event rupture detection. **Feasibility:** DAS interrogators can be installed at cable landing stations, and fiber-optic seismic sensing is already proven. Ocean-noise denoising with ML is mature, and a pilot on one cable could be validated against ocean-bottom seismometers at modest cost compared with new permanent offshore arrays. | I28: =IF($E28="","",IFERROR(VLOOKUP($E28,题目信息!$B$5:$J$253,9,0),"")) -> 无固定答案（官方LLM评审） | J28: 9 | K28: =IF($E28="","",IFERROR(VLOOKUP($E28,题目信息!$B$5:$L$253,11,0),10)) -> 10 | L28: =IF(OR($J28="",$K28=""),"",$J28/$K28) -> 0.9 | M28: LLM评审 | N28: 分析： - 要求核对：① 围绕关键词 earthquakes——符合；② 英文写作——符合；③ 给出一个新颖且可行的研究想法——符合；④ 分别说明 idea / novelty / feasibility——三部分显式标注，齐全；⑤ 字数≤150——全文约121词，符合；⑥ 格式与禁用项——无格式违规，无禁用内容。 - 新颖性（orig，满分4）：将海底通信光纤DAS用于地震监测已是近年公开研究的热点方向（海底DAS阵列、微震检测均有文献先例），本回答属于该方向的集成式延伸，而非全新范式；加分点在于把目标明确锚定在"慢滑动前兆"而非震后破裂探测，并引入物理信息机器学习做弱信号与海洋噪声分离，具 | O28: 2026-10-23 | P28: 自动写入 | Q28: 1421 | R28: 1621 | S28: 0.0027 | T28: 1746 | U28: 2412 | W28: 9.37
B29: R0025 | C29: M01 | D29: =IF($C29="","",IFERROR(VLOOKUP($C29,模型信息!$B$5:$C$24,2,0),"未登记")) -> DeepSeek-V4-Flash | E29: CR05 | F29: =IF($E29="","",IFERROR(VLOOKUP($E29,题目信息!$B$5:$C$253,2,0),"未登记")) -> 创造力 | G29: 1 | H29: **Idea:** A “wide-binary age laboratory”: use Gaia astrometry to identify thousands of wide binary pairs and TESS photometry to measure rotation periods and solar-like oscillations for both components. Because wide-binary stars are coeval but have different masses, they provide internal age calibration for field stars. **Novelty:** It cross-calibrates gyrochronology and asteroseismic scaling relations at the individual-system level, rather than relying on cluster averages, and tests age-dating methods where stellar activity and oscillations can be measured simultaneously. **Feasibility:** Gaia DR3 and TESS provide public, homogeneous data; existing asteroseismic and rotation-period pipelines can be applied. A statistical sample of wide binaries can be assembled and analyzed within current computational resources. | I29: =IF($E29="","",IFERROR(VLOOKUP($E29,题目信息!$B$5:$J$253,9,0),"")) -> 无固定答案（官方LLM评审） | J29: 8 | K29: =IF($E29="","",IFERROR(VLOOKUP($E29,题目信息!$B$5:$L$253,11,0),10)) -> 10 | L29: =IF(OR($J29="",$K29=""),"",$J29/$K29) -> 0.8 | M29: LLM评审 | N29: 分析：题目要求围绕关键词 stars 提出一个新颖且可行的科研想法，用英文在 150 词内说明想法、新颖性和可行性。模型回答逐项满足：主题与 stars 相关；英文表达；结构包含 Idea、Novelty、Feasibility；字数约 **108 词**，未超限；无格式或禁用词硬伤。新颖性方面，将宽双星作为“年龄实验室”，在单个系统层面交叉校准陀螺年代学与星震学定龄方法，有一定新意，但属于已有方法组合的增量创新，给 **3/4**。可行性方面，Gaia DR3 与 TESS 数据公开，旋转周期测量可行；但声称用 TESS 对“数千”宽双星双组分测量类太阳振荡偏乐观，星震学探测受亮度与信噪比限 | O29: 2026-10-23 | P29: 自动写入 | Q29: 1421 | R29: 1412 | S29: 0.0024 | T29: 1734 | U29: 2475 | W29: 7.17
B30: R0026 | C30: M01 | D30: =IF($C30="","",IFERROR(VLOOKUP($C30,模型信息!$B$5:$C$24,2,0),"未登记")) -> DeepSeek-V4-Flash | E30: CR06 | F30: =IF($E30="","",IFERROR(VLOOKUP($E30,题目信息!$B$5:$C$253,2,0),"未登记")) -> 创造力 | G30: 1 | H30: **Idea:** Develop an acoustic early-warning system for hurricane rapid intensification (RI) by training deep-learning models on underwater sound recorded by existing hydrophone arrays, combined with satellite sea-surface temperature and Argo profiles. **Why novel:** Most RI prediction relies on satellite and airborne observations of the storm and upper ocean. This approach uses the ocean soundscape—breaking waves, bubble injection, and rain noise—as an integrated proxy for air–sea momentum and heat exchange, a signal not yet exploited operationally for RI forecasting. **Why feasible:** Global hydrophone networks, Argo floats, and satellite altimetry already provide decades of overlapping data. Historical hurricane tracks allow supervised labeling of RI events, and low-cost hydrophone additions can fill regional gaps. A proof-of-concept could be tested retrospectively on Atlantic and Pacific storms within 2–3 years. | I30: =IF($E30="","",IFERROR(VLOOKUP($E30,题目信息!$B$5:$J$253,9,0),"")) -> 无固定答案（官方LLM评审） | J30: 8 | K30: =IF($E30="","",IFERROR(VLOOKUP($E30,题目信息!$B$5:$L$253,11,0),10)) -> 10 | L30: =IF(OR($J30="",$K30=""),"",$J30/$K30) -> 0.8 | M30: LLM评审 | N30: 分析：逐条核对：(1) 语言为英文，符合要求；(2) 字数约127词，未超过150词上限，符合；(3) 明确给出研究想法（用水听器阵列水下声学+卫星SST+Argo剖面训练深度学习模型，预警飓风快速增强RI），符合；(4) 明确说明新颖性（现有RI预报依赖卫星/机载观测，而海洋声景作为海气动量与热量交换的综合代理尚未被业务化用于RI预报），论证具体且有针对性，符合；(5) 明确说明可行性（全球水听器网络、Argo、卫星高度计已有数十年重叠数据；历史路径可提供RI监督标签；低成本补充部署可填补区域空白；2–3年内可回溯验证），符合；(6) 格式为分点小标题式，结构清晰，符合。 评分要点核对：新 | O30: 2026-10-23 | P30: 自动写入 | Q30: 1421 | R30: 1393 | S30: 0.0024 | T30: 1750 | U30: 1977 | W30: 10.13
B31: R0027 | C31: M01 | D31: =IF($C31="","",IFERROR(VLOOKUP($C31,模型信息!$B$5:$C$24,2,0),"未登记")) -> DeepSeek-V4-Flash | E31: CR07 | F31: =IF($E31="","",IFERROR(VLOOKUP($E31,题目信息!$B$5:$C$253,2,0),"未登记")) -> 创造力 | G31: 1 | H31: **Research idea:** Develop a phycosphere-informed probiotic consortium to stabilize microalgal cultivation in open raceway ponds. Isolate algae-associated bacteria from locally adapted green algae, screen for traits such as vitamin B12 provision and reactive-oxygen scavenging, then test a defined 3–5 strain consortium for biomass and lipid productivity under fluctuating light and temperature. **Why novel:** Most algal probiotics are selected empirically; this approach links phycosphere ecology to functional trait selection and community stability, producing a reproducible, ecology-based inoculant. **Why feasible:** Native algae and bacteria are readily isolated; screening uses standard plate assays, flow cytometry, and amplicon sequencing; small raceway mesocosms can test consortia within 6–9 months. The output would be a candidate probiotic and design rules for phycosphere management in biofuel and bioproduct cultivation. | I31: =IF($E31="","",IFERROR(VLOOKUP($E31,题目信息!$B$5:$J$253,9,0),"")) -> 无固定答案（官方LLM评审） | J31: 9 | K31: =IF($E31="","",IFERROR(VLOOKUP($E31,题目信息!$B$5:$L$253,11,0),10)) -> 10 | L31: =IF(OR($J31="",$K31=""),"",$J31/$K31) -> 0.9 | M31: LLM评审 | N31: 分析：要求为围绕关键词 phycology 提出一个新颖且可行的英文研究想法，并说明想法、新颖性、可行性，且不超过150词。模型回答完整覆盖三项：提出“phycosphere-informed probiotic consortium”用于稳定开放跑道池微藻培养；说明新颖性在于将藻际生态与功能性状筛选、群落稳定性结合；说明可行性在于本地藻菌易分离、标准筛选与测序手段成熟、6–9个月中型跑道池验证可行。英文表达流畅、结构清晰，字数约122词，符合150词限制，未违反硬约束。扣分点：新颖性属于已有藻际微生物/益生菌思路的合理组合，创新强度中等，未达到突破性程度，因此新颖性给3/4；可行性高，给3/ | O31: 2026-10-23 | P31: 自动写入 | Q31: 1423 | R31: 1962 | S31: 0.0032 | T31: 1757 | U31: 2699 | W31: 12.3
B32: R0028 | C32: M01 | D32: =IF($C32="","",IFERROR(VLOOKUP($C32,模型信息!$B$5:$C$24,2,0),"未登记")) -> DeepSeek-V4-Flash | E32: CR08 | F32: =IF($E32="","",IFERROR(VLOOKUP($E32,题目信息!$B$5:$C$253,2,0),"未登记")) -> 创造力 | G32: 1 | H32: **Idea:** Measure the three-dimensional dark-matter shapes of Local Group galaxies by combining stellar-stream gaps with resolved rotation curves. **Novelty:** Most galaxy-shape measurements rely on lensing or gas kinematics, which poorly constrain triaxiality at small radii. Stellar-stream gaps directly trace subhalo populations and halo ellipticity, offering a new test of cold dark matter predictions on dwarf-galaxy scales. **Feasibility:** Rubin/LSST will provide deep, wide-field photometry of streams in the Milky Way and Local Group dwarfs; existing simulations (FIRE, Auriga) supply mock observables for pipeline validation. A pilot using DESI Legacy Imaging and Gaia proper motions can calibrate detection thresholds before LSST. This links galaxies, dark matter, and stream archaeology using data expected within the next few years. | I32: =IF($E32="","",IFERROR(VLOOKUP($E32,题目信息!$B$5:$J$253,9,0),"")) -> 无固定答案（官方LLM评审） | J32: 10 | K32: =IF($E32="","",IFERROR(VLOOKUP($E32,题目信息!$B$5:$L$253,11,0),10)) -> 10 | L32: =IF(OR($J32="",$K32=""),"",$J32/$K32) -> 1 | M32: LLM评审 | N32: 分析： - **要求核对**：①英文作答——符合；②字数≤150词——全文约 **120词**，符合；③明确“陈述想法+新颖性+可行性”三要素——以 Idea/Novelty/Feasibility 三段清晰对应，符合；④紧扣关键词 galaxies——以本星系群星系暗物质晕三维形状为核心，符合。 - **新颖性（4分）**：将“星流间隙（stream gaps）”与“分辨旋转曲线”联合，约束小半径处暗物质晕的三轴比，避开传统弱引力透镜/气体运动学的半径与投影限制，并提出对 CDM 矮星系尺度预言的检验，思路具体且不落俗套，可得 **4分**。 - **可行性（3分）**：给出 L | O32: 2026-10-23 | P32: 自动写入 | Q32: 1421 | R32: 2119 | S32: 0.0034 | T32: 1747 | U32: 1776 | W32: 15
B33: R0029 | C33: M01 | D33: =IF($C33="","",IFERROR(VLOOKUP($C33,模型信息!$B$5:$C$24,2,0),"未登记")) -> DeepSeek-V4-Flash | E33: CR09 | F33: =IF($E33="","",IFERROR(VLOOKUP($E33,题目信息!$B$5:$C$253,2,0),"未登记")) -> 创造力 | G33: 1 | H33: **Idea:** A citizen-science GPS reflectometry network using smartphone raw GPS measurements to map urban flood depth. Crowdsourced L1/L5 signal-to-noise and carrier-phase data from everyday phones would detect water-induced multipath changes and estimate surface water depth after calibration. **Novelty:** It repurposes existing GPS receivers as dense, zero-hardware flood sensors, complementing sparse gauges and satellite imagery with street-level observations. **Feasibility:** Android devices expose raw GPS/GNSS measurements; existing apps can log them. A small calibration campaign with controlled water depths and machine-learning inversion could validate the approach, making city-scale deployment practical and low-cost. | I33: =IF($E33="","",IFERROR(VLOOKUP($E33,题目信息!$B$5:$J$253,9,0),"")) -> 无固定答案（官方LLM评审） | J33: 8 | K33: =IF($E33="","",IFERROR(VLOOKUP($E33,题目信息!$B$5:$L$253,11,0),10)) -> 10 | L33: =IF(OR($J33="",$K33=""),"",$J33/$K33) -> 0.8 | M33: LLM评审 | N33: 分析：要求为基于关键词 global positioning system 提出一个新颖且可行的科研想法，英文、150词内，并说明想法、新颖性、可行性。模型回答完整覆盖三点：提出智能手机原始GPS反射测量市民科学洪水深度制图网络；新颖性说明复用现有GPS接收器为密集低成本洪水传感器；可行性说明Android原始GNSS数据、现有应用记录、校准与机器学习反演。语言为英文，约90词，符合150词限制；格式清晰，无禁用词或明显硬约束违反。按官方维度评估：新颖性中等偏上，属GNSS-R、洪水监测与智能手机众包的组合创新，但核心组件并非全新，给3/4；可行性较合理，但用智能手机多径/载波相位反演水深精度 | O33: 2026-10-23 | P33: 自动写入 | Q33: 1423 | R33: 1470 | S33: 0.0025 | T33: 1716 | U33: 1771 | W33: 7.24
B34: R0030 | C34: M01 | D34: =IF($C34="","",IFERROR(VLOOKUP($C34,模型信息!$B$5:$C$24,2,0),"未登记")) -> DeepSeek-V4-Flash | E34: CR10 | F34: =IF($E34="","",IFERROR(VLOOKUP($E34,题目信息!$B$5:$C$253,2,0),"未登记")) -> 创造力 | G34: 1 | H34: **Idea:** Develop DNA-origami “virus traps” that display clustered ACE2-mimetic receptors alongside a furin-cleavable fluorescent reporter, enabling label-free detection of infectious coronaviruses in environmental samples. **Why novel:** The platform mimics the spatial receptor clustering and proteolytic activation used during viral entry, rather than detecting viral RNA or antigens alone; this could distinguish infectious from non-infectious viruses. **Why feasible:** DNA origami is programmable and scalable; ACE2-mimetic peptides and furin substrates are well characterized; fluorescence readout requires only standard plate readers. Initial validation can use pseudotyped viruses and wastewater samples, with biosafety contained. | I34: =IF($E34="","",IFERROR(VLOOKUP($E34,题目信息!$B$5:$J$253,9,0),"")) -> 无固定答案（官方LLM评审） | J34: 9 | K34: =IF($E34="","",IFERROR(VLOOKUP($E34,题目信息!$B$5:$L$253,11,0),10)) -> 10 | L34: =IF(OR($J34="",$K34=""),"",$J34/$K34) -> 0.9 | M34: LLM评审 | N34: 分析：要求为英文、150词内、围绕 viruses 提出一个新颖可行研究想法，并说明想法、创新性、可行性。模型回答为英文，约90词，符合字数；明确给出 idea、why novel、why feasible，内容与病毒检测相关。新颖性较强：将DNA折纸、ACE2模拟受体空间簇集与furin切割荧光报告结合，用于区分感染性与非感染性冠状病毒，思路具体且有区分度，给4/4。可行性总体合理：DNA折纸可编程、ACE2模拟肽与furin底物已有基础，假病毒和污水样本初筛路径清楚；但“label-free”与荧光报告表述略矛盾，环境样本灵敏度、特异性及规模化验证未充分展开，给2.5/3，按整数评分体现为 | O34: 2026-10-23 | P34: 自动写入 | Q34: 1421 | R34: 1517 | S34: 0.0026 | T34: 1715 | U34: 2500 | W34: 8.49
B35: R0031 | C35: M01 | D35: =IF($C35="","",IFERROR(VLOOKUP($C35,模型信息!$B$5:$C$24,2,0),"未登记")) -> DeepSeek-V4-Flash | E35: CR11 | F35: =IF($E35="","",IFERROR(VLOOKUP($E35,题目信息!$B$5:$C$253,2,0),"未登记")) -> 创造力 | G35: 1 | H35: **Idea:** A 12-week feasibility trial of a smartphone-based “digital speech relapse signature” in first-episode schizophrenia. Participants complete weekly 2-minute free-speech samples; automated NLP measures lexical coherence and prosodic flattening are combined with passive mobility/actigraphy data to predict symptom exacerbation. Clinicians receive stepped-care alerts. **Novelty:** It prospectively integrates linguistic coherence and passive behavioral markers specifically in first-episode patients, rather than using cross-sectional speech analysis or single-modality monitoring. **Feasibility:** Smartphones and existing speech-NLP pipelines enable low-burden data collection. A pilot of 40 participants can test acceptability, data quality, and preliminary predictive validity against standardized symptom and relapse assessments, providing effect-size estimates for a larger trial. | I35: =IF($E35="","",IFERROR(VLOOKUP($E35,题目信息!$B$5:$J$253,9,0),"")) -> 无固定答案（官方LLM评审） | J35: 9 | K35: =IF($E35="","",IFERROR(VLOOKUP($E35,题目信息!$B$5:$L$253,11,0),10)) -> 10 | L35: =IF(OR($J35="",$K35=""),"",$J35/$K35) -> 0.9 | M35: LLM评审 | N35: 分析：题目要求围绕 schizophrenia 提出一个新颖、可行、英文、150词以内的科研想法，并说明想法、创新性和可行性。模型回答明确聚焦 first-episode schizophrenia，提出智能手机语音+被动行为数据的12周可行性试验，属于相关研究想法；明确写了 Novelty 和 Feasibility；全文约100词，符合150词限制；英文表达流畅，结构清楚。硬约束方面：包含关键词 schizophrenia，无禁用词，格式无问题。评分要点：新颖性较好，将语音连贯性、韵律扁平化与被动移动/活动数据结合，并聚焦首发患者的前瞻性预警，但数字表型、语音NLP和复发预测均已有较多相关 | O35: 2026-10-23 | P35: 自动写入 | Q35: 1421 | R35: 1504 | S35: 0.0026 | T35: 1736 | U35: 2137 | W35: 8.79
B36: R0032 | C36: M01 | D36: =IF($C36="","",IFERROR(VLOOKUP($C36,模型信息!$B$5:$C$24,2,0),"未登记")) -> DeepSeek-V4-Flash | E36: CR12 | F36: =IF($E36="","",IFERROR(VLOOKUP($E36,题目信息!$B$5:$C$253,2,0),"未登记")) -> 创造力 | G36: 1 | H36: **Idea:** Use existing dark fiber-optic telecom cables as distributed acoustic sensing (DAS) arrays to image near-ground tornado wind fields and track vortex structure in real time. **Novelty:** Most tornado sensing relies on radar, which struggles below the horizon and near the surface. Repurposing regional fiber networks as dense, kilometer-scale acoustic arrays could reveal tornado–ground coupling, debris loading, and low-level wind asymmetries at unprecedented resolution. **Feasibility:** DAS interrogators can be deployed on existing fiber in tornado-prone regions such as Oklahoma and Kansas. Machine-learning denoising can separate tornado signals from traffic and weather noise, and calibration against radar, mesonets, and damage surveys is straightforward. The approach is low-cost, scalable, and testable during the next tornado season. | I36: =IF($E36="","",IFERROR(VLOOKUP($E36,题目信息!$B$5:$J$253,9,0),"")) -> 无固定答案（官方LLM评审） | J36: 10 | K36: =IF($E36="","",IFERROR(VLOOKUP($E36,题目信息!$B$5:$L$253,11,0),10)) -> 10 | L36: =IF(OR($J36="",$K36=""),"",$J36/$K36) -> 1 | M36: LLM评审 | N36: 分析：关键词为 tornadoes，回答提出用现有暗光纤电信电缆作为分布式声学传感（DAS）阵列来成像近地面龙卷风风场并追踪涡旋结构，符合“一个相关研究想法”的要求。回答为英文，约 **114** 词，未超过 **150** 词。内容明确包含 Idea、Novelty、Feasibility 三部分：想法具体；新颖性体现在区别于雷达、利用既有光纤网络进行近地面高分辨率观测；可行性体现在 DAS interrogators、龙卷风多发区既有光纤、机器学习去噪及雷达/气象站/灾调校准，且可测试、低成本、可扩展。硬约束无违反。按评分要点：新颖性 **4/4**，可行性 **3/3**，流畅性 ** | O36: 2026-10-23 | P36: 自动写入 | Q36: 1422 | R36: 1398 | S36: 0.0024 | T36: 1742 | U36: 2350 | W36: 6.49
B37: R0033 | C37: M01 | D37: =IF($C37="","",IFERROR(VLOOKUP($C37,模型信息!$B$5:$C$24,2,0),"未登记")) -> DeepSeek-V4-Flash | E37: CR13 | F37: =IF($E37="","",IFERROR(VLOOKUP($E37,题目信息!$B$5:$C$253,2,0),"未登记")) -> 创造力 | G37: 1 | H37: **Idea:** Jointly analyze pulsar-timing-array gravitational-wave background anisotropies and Planck CMB maps to test whether the hot Big Bang was preceded by a brief matter-dominated reheating phase. Such a phase would imprint a characteristic quadrupole in the nanohertz background and a correlated large-scale CMB power deficit. **Novelty:** Existing studies treat these datasets separately; their cross-correlation has not been used as a model-independent probe of pre-Big Bang expansion. **Feasibility:** NANOGrav/EPTA data already constrain the isotropic background, SKA will improve anisotropy sensitivity, and Planck maps are public. The analysis needs only Bayesian cross-spectral pipelines, not new hardware. | I37: =IF($E37="","",IFERROR(VLOOKUP($E37,题目信息!$B$5:$J$253,9,0),"")) -> 无固定答案（官方LLM评审） | J37: 0 | K37: =IF($E37="","",IFERROR(VLOOKUP($E37,题目信息!$B$5:$L$253,11,0),10)) -> 10 | L37: =IF(OR($J37="",$K37=""),"",$J37/$K37) -> 0 | M37: LLM评审 | N37: 评审调用失败: 调用失败(重试2次): <urlopen error _ssl.c:1015: The handshake operation timed out> | O37: 2026-10-23 | P37: 自动写入 | Q37: 1423 | R37: 1938 | S37: 0.0032 | W37: 13.14
B38: R0034 | C38: M01 | D38: =IF($C38="","",IFERROR(VLOOKUP($C38,模型信息!$B$5:$C$24,2,0),"未登记")) -> DeepSeek-V4-Flash | E38: CR14 | F38: =IF($E38="","",IFERROR(VLOOKUP($E38,题目信息!$B$5:$C$253,2,0),"未登记")) -> 创造力 | G38: 1 | H38: **Idea:** Engineer a gut-colonizing probiotic biosensor that detects parasite-derived cysteine proteases and produces a colorimetric stool reporter, enabling non-invasive helminth surveillance. **Why novel:** Current parasite diagnostics rely on microscopy, antigen tests, or DNA, which need sampling and lab infrastructure. A living in-gut sensor links parasite-specific enzymatic activity to a visible output and could distinguish active infection from residual DNA. **Why feasible:** Well-characterized *E. coli* Nissl 1917 and *Lactobacillus* chassis exist; protease-responsive promoters can be built from known cleavage sites; helminth proteases are abundant in stool. Proof-of-concept would use *Trichuris muris* or *Heligmosomoides polygyrus* in mice, engineered strains with a protease sensor, and stool color readout. Specificity can be tuned with protease inhibitors and negative controls; biosafety can include kill switches. The project fits standard microbiology, synthetic biology, and parasitology labs within 18–24 months. | I38: =IF($E38="","",IFERROR(VLOOKUP($E38,题目信息!$B$5:$J$253,9,0),"")) -> 无固定答案（官方LLM评审） | J38: 9 | K38: =IF($E38="","",IFERROR(VLOOKUP($E38,题目信息!$B$5:$L$253,11,0),10)) -> 10 | L38: =IF(OR($J38="",$K38=""),"",$J38/$K38) -> 0.9 | M38: LLM评审 | N38: 分析：要求均满足：用英文提出一个与 parasites 相关的新颖可行研究想法；明确陈述了 idea、novelty 和 feasibility；全文约 **133 词**，未超 **150 词**；无格式或禁用词问题。评分要点方面：新颖性较强，将工程益生菌体内生物传感器用于寄生虫蛋白酶检测并产生粪便显色报告，区别于显微、抗原和 DNA 检测，可得 **4/4** 或接近满分；可行性有合理依据，包括已知底盘、蛋白酶响应启动子、小鼠模型和生物安全开关，但体内信号强度、粪便背景干扰、宿主蛋白酶交叉反应及定植控制仍有挑战，略扣分，约 **2.5/3**；流畅性清晰，结构完整，表达自然，可得 **3/ | O38: 2026-10-23 | P38: 自动写入 | Q38: 1421 | R38: 1945 | S38: 0.0032 | T38: 1789 | U38: 2158 | W38: 11.04
